Fortnox tokens refreshed!
starting script..
days since OC token was created: 0
rows in wise completed:
3
All rows from OC:
1473
rows in joined list:
3
script finished!
Error: 400 - {"error":"invalid_grant","error_description":"Invalid refresh token"}
Traceback (most recent call last):
  File "/home/viktor/Documents/OC-coding/OC-Wise-Fortnox-integration/fortnox_exchange_refresh_token.py", line 41, in <module>
    set_key('.env', 'fortnox_access_token', access_token)
NameError: name 'access_token' is not defined
starting script..
days since OC token was created: 0
rows in wise completed:
9
All rows from OC:
1473
Email sent successfully!
rows in joined list:
8
booked voucher: 4 with connected file: https://api.fortnox.se/3/voucherfileconnections/2fd5f3ec-cede-47a7-8718-9697a7eebb18
booked voucher: 5 with connected file: https://api.fortnox.se/3/voucherfileconnections/0bb6d364-981f-4268-889d-bbed615efea6
booked voucher: 6 with connected file: https://api.fortnox.se/3/voucherfileconnections/d008d784-5f5c-4955-937b-f2b0301856f5
booked voucher: 7 with connected file: https://api.fortnox.se/3/voucherfileconnections/87fd3639-85db-485a-82cf-5b72a717bdf1
booked voucher: 8 with connected file: https://api.fortnox.se/3/voucherfileconnections/e0726630-98da-4833-9866-f0a659daaf9f
Script ran successfully at: 2023-11-14
-------------------------------------------------------------------------------------------------------
script finished!
Fortnox tokens refreshed!
starting script..
days since OC token was created: 1
rows in wise completed:
9
All rows from OC:
1473
rows in joined list:
8
Script ran successfully at: 2023-11-15
-------------------------------------------------------------------------------------------------------

script finished!
Error: 400 - {"error":"invalid_grant","error_description":"Invalid refresh token"}
Traceback (most recent call last):
  File "/home/viktor/Documents/OC-coding/OC-Wise-Fortnox-integration/fortnox_exchange_refresh_token.py", line 41, in <module>
    set_key('.env', 'fortnox_access_token', access_token)
NameError: name 'access_token' is not defined
starting script..
days since OC token was created: 2
rows in wise completed:
9
All rows from OC:
1473
rows in joined list:
8
Script ran successfully at: 2023-11-16
-------------------------------------------------------------------------------------------------------

script finished!
Error: 400 - {"error":"invalid_grant","error_description":"Invalid refresh token"}
Traceback (most recent call last):
  File "/home/viktor/Documents/OC-coding/OC-Wise-Fortnox-integration/fortnox_exchange_refresh_token.py", line 41, in <module>
    set_key('.env', 'fortnox_access_token', access_token)
NameError: name 'access_token' is not defined
starting script..
days since OC token was created: 3
rows in wise completed:
9
All rows from OC:
1473
rows in joined list:
8
Script ran successfully at: 2023-11-17
-------------------------------------------------------------------------------------------------------

script finished!
Error: 400 - {"error":"invalid_grant","error_description":"Invalid refresh token"}
Traceback (most recent call last):
  File "/home/viktor/Documents/OC-coding/OC-Wise-Fortnox-integration/fortnox_exchange_refresh_token.py", line 41, in <module>
    set_key('.env', 'fortnox_access_token', access_token)
NameError: name 'access_token' is not defined
starting script..
days since OC token was created: 6
rows in wise completed:
9
All rows from OC:
1473
rows in joined list:
8
Script ran successfully at: 2023-11-20
-------------------------------------------------------------------------------------------------------

script finished!
Error: 400 - {"error":"invalid_grant","error_description":"Invalid refresh token"}
Traceback (most recent call last):
  File "/home/viktor/Documents/OC-coding/OC-Wise-Fortnox-integration/fortnox_exchange_refresh_token.py", line 41, in <module>
    set_key('.env', 'fortnox_access_token', access_token)
NameError: name 'access_token' is not defined
starting script..
days since OC token was created: 9
rows in wise completed:
9
All rows from OC:
1473
rows in joined list:
8
Script ran successfully at: 2023-11-23
-------------------------------------------------------------------------------------------------------

script finished!
Error: 400 - {"error":"invalid_grant","error_description":"Invalid refresh token"}
Traceback (most recent call last):
  File "/home/viktor/Documents/OC-coding/OC-Wise-Fortnox-integration/fortnox_exchange_refresh_token.py", line 41, in <module>
    set_key('.env', 'fortnox_access_token', access_token)
NameError: name 'access_token' is not defined
starting script..
days since OC token was created: 10
rows in wise completed:
9
All rows from OC:
1474
rows in joined list:
8
Script ran successfully at: 2023-11-24
-------------------------------------------------------------------------------------------------------

script finished!
Error: 400 - {"error":"invalid_grant","error_description":"Invalid refresh token"}
Traceback (most recent call last):
  File "/home/viktor/Documents/OC-coding/OC-Wise-Fortnox-integration/fortnox_exchange_refresh_token.py", line 41, in <module>
    set_key('.env', 'fortnox_access_token', access_token)
NameError: name 'access_token' is not defined
starting script..
days since OC token was created: 14
rows in wise completed:
9
All rows from OC:
1474
rows in joined list:
8
Script ran successfully at: 2023-11-28
-------------------------------------------------------------------------------------------------------

script finished!
Fortnox tokens refreshed!
starting script..
days since OC token was created: 16
rows in wise completed:
9
All rows from OC:
1474
Transfer not found email sent successfully!
rows in joined list:
8
Script ran successfully at: 2023-11-30
-------------------------------------------------------------------------------------------------------

script finished!
Fortnox tokens refreshed!
starting script..
days since OC token was created: 20
rows in wise completed:
9
All rows from OC:
1474
rows in joined list:
8
Script ran successfully at: 2023-12-04
-------------------------------------------------------------------------------------------------------

script finished!
Fortnox tokens refreshed!
starting script..
days since OC token was created: 22
rows in wise completed:
9
All rows from OC:
1474
rows in joined list:
8
Script ran successfully at: 2023-12-06
-------------------------------------------------------------------------------------------------------

script finished!
Error: 400 - {"error":"invalid_grant","error_description":"Invalid refresh token"}
Traceback (most recent call last):
  File "/home/viktor/Documents/OC-coding/OC-Wise-Fortnox-integration/fortnox_exchange_refresh_token.py", line 44, in <module>
    set_key(f'{relative_path}.env', 'fortnox_access_token', access_token)
NameError: name 'access_token' is not defined
starting script..
days since OC token was created: 23
rows in wise completed:
9
All rows from OC:
1474
rows in joined list:
8
Script ran successfully at: 2023-12-07
-------------------------------------------------------------------------------------------------------

script finished!
Fortnox tokens refreshed!
starting script..
days since OC token was created: 24
rows in wise completed:
9
All rows from OC:
1474
rows in joined list:
8
Script ran successfully at: 2023-12-08
-------------------------------------------------------------------------------------------------------

script finished!
Fortnox tokens refreshed!
starting script..
days since OC token was created: 25
rows in wise completed:
9
All rows from OC:
1474
rows in joined list:
8
Script ran successfully at: 2023-12-09
-------------------------------------------------------------------------------------------------------

script finished!
Traceback (most recent call last):
  File "/usr/lib/python3/dist-packages/urllib3/connection.py", line 169, in _new_conn
    conn = connection.create_connection(
  File "/usr/lib/python3/dist-packages/urllib3/util/connection.py", line 73, in create_connection
    for res in socket.getaddrinfo(host, port, family, socket.SOCK_STREAM):
  File "/usr/lib/python3.10/socket.py", line 955, in getaddrinfo
    for res in _socket.getaddrinfo(host, port, family, type, proto, flags):
socket.gaierror: [Errno -3] Temporary failure in name resolution

During handling of the above exception, another exception occurred:

Traceback (most recent call last):
  File "/usr/lib/python3/dist-packages/urllib3/connectionpool.py", line 700, in urlopen
    httplib_response = self._make_request(
  File "/usr/lib/python3/dist-packages/urllib3/connectionpool.py", line 383, in _make_request
    self._validate_conn(conn)
  File "/usr/lib/python3/dist-packages/urllib3/connectionpool.py", line 1017, in _validate_conn
    conn.connect()
  File "/usr/lib/python3/dist-packages/urllib3/connection.py", line 353, in connect
    conn = self._new_conn()
  File "/usr/lib/python3/dist-packages/urllib3/connection.py", line 181, in _new_conn
    raise NewConnectionError(
urllib3.exceptions.NewConnectionError: <urllib3.connection.HTTPSConnection object at 0x7fa66c561900>: Failed to establish a new connection: [Errno -3] Temporary failure in name resolution

During handling of the above exception, another exception occurred:

Traceback (most recent call last):
  File "/usr/lib/python3/dist-packages/requests/adapters.py", line 439, in send
    resp = conn.urlopen(
  File "/usr/lib/python3/dist-packages/urllib3/connectionpool.py", line 756, in urlopen
    retries = retries.increment(
  File "/usr/lib/python3/dist-packages/urllib3/util/retry.py", line 574, in increment
    raise MaxRetryError(_pool, url, error or ResponseError(cause))
urllib3.exceptions.MaxRetryError: HTTPSConnectionPool(host='apps.fortnox.se', port=443): Max retries exceeded with url: /oauth-v1/token (Caused by NewConnectionError('<urllib3.connection.HTTPSConnection object at 0x7fa66c561900>: Failed to establish a new connection: [Errno -3] Temporary failure in name resolution'))

During handling of the above exception, another exception occurred:

Traceback (most recent call last):
  File "/home/viktor/Documents/OC-coding/OC-Wise-Fortnox-integration/fortnox_exchange_refresh_token.py", line 30, in <module>
    response = requests.post(token_url, headers=auth_header, data=data)
  File "/usr/lib/python3/dist-packages/requests/api.py", line 119, in post
    return request('post', url, data=data, json=json, **kwargs)
  File "/usr/lib/python3/dist-packages/requests/api.py", line 61, in request
    return session.request(method=method, url=url, **kwargs)
  File "/usr/lib/python3/dist-packages/requests/sessions.py", line 544, in request
    resp = self.send(prep, **send_kwargs)
  File "/usr/lib/python3/dist-packages/requests/sessions.py", line 657, in send
    r = adapter.send(request, **kwargs)
  File "/usr/lib/python3/dist-packages/requests/adapters.py", line 516, in send
    raise ConnectionError(e, request=request)
requests.exceptions.ConnectionError: HTTPSConnectionPool(host='apps.fortnox.se', port=443): Max retries exceeded with url: /oauth-v1/token (Caused by NewConnectionError('<urllib3.connection.HTTPSConnection object at 0x7fa66c561900>: Failed to establish a new connection: [Errno -3] Temporary failure in name resolution'))
starting script..
days since OC token was created: 26
An error occurred: HTTPSConnectionPool(host='raw.githubusercontent.com', port=443): Max retries exceeded with url: /zaunders/OC-Wise-Fortnox-integration/main/fortnox_account_lookup.json (Caused by NewConnectionError('<urllib3.connection.HTTPSConnection object at 0x7f58d2a65b70>: Failed to establish a new connection: [Errno -3] Temporary failure in name resolution'))
An error occurred: HTTPSConnectionPool(host='api.transferwise.com', port=443): Max retries exceeded with url: /v1/transfers?profile=25518118&limit=100&createdDateStart=2023-09-10&createdDateEnd=2023-09-30&offset=0 (Caused by NewConnectionError('<urllib3.connection.HTTPSConnection object at 0x7f58d2a666b0>: Failed to establish a new connection: [Errno -3] Temporary failure in name resolution'))
Traceback (most recent call last):
  File "/usr/lib/python3/dist-packages/urllib3/connection.py", line 169, in _new_conn
    conn = connection.create_connection(
  File "/usr/lib/python3/dist-packages/urllib3/util/connection.py", line 73, in create_connection
    for res in socket.getaddrinfo(host, port, family, socket.SOCK_STREAM):
  File "/usr/lib/python3.10/socket.py", line 955, in getaddrinfo
    for res in _socket.getaddrinfo(host, port, family, type, proto, flags):
socket.gaierror: [Errno -3] Temporary failure in name resolution

During handling of the above exception, another exception occurred:

Traceback (most recent call last):
  File "/usr/lib/python3/dist-packages/urllib3/connectionpool.py", line 700, in urlopen
    httplib_response = self._make_request(
  File "/usr/lib/python3/dist-packages/urllib3/connectionpool.py", line 383, in _make_request
    self._validate_conn(conn)
  File "/usr/lib/python3/dist-packages/urllib3/connectionpool.py", line 1017, in _validate_conn
    conn.connect()
  File "/usr/lib/python3/dist-packages/urllib3/connection.py", line 353, in connect
    conn = self._new_conn()
  File "/usr/lib/python3/dist-packages/urllib3/connection.py", line 181, in _new_conn
    raise NewConnectionError(
urllib3.exceptions.NewConnectionError: <urllib3.connection.HTTPSConnection object at 0x7f58d2a666b0>: Failed to establish a new connection: [Errno -3] Temporary failure in name resolution

During handling of the above exception, another exception occurred:

Traceback (most recent call last):
  File "/usr/lib/python3/dist-packages/requests/adapters.py", line 439, in send
    resp = conn.urlopen(
  File "/usr/lib/python3/dist-packages/urllib3/connectionpool.py", line 756, in urlopen
    retries = retries.increment(
  File "/usr/lib/python3/dist-packages/urllib3/util/retry.py", line 574, in increment
    raise MaxRetryError(_pool, url, error or ResponseError(cause))
urllib3.exceptions.MaxRetryError: HTTPSConnectionPool(host='api.transferwise.com', port=443): Max retries exceeded with url: /v1/transfers?profile=25518118&limit=100&createdDateStart=2023-09-10&createdDateEnd=2023-09-30&offset=0 (Caused by NewConnectionError('<urllib3.connection.HTTPSConnection object at 0x7f58d2a666b0>: Failed to establish a new connection: [Errno -3] Temporary failure in name resolution'))

During handling of the above exception, another exception occurred:

Traceback (most recent call last):
  File "/home/viktor/Documents/OC-coding/OC-Wise-Fortnox-integration/script_get_wise_transactions_book_and_match.py", line 106, in <module>
    response = requests.get(api_url, headers=headers, params={"offset": offset})
  File "/usr/lib/python3/dist-packages/requests/api.py", line 76, in get
    return request('get', url, params=params, **kwargs)
  File "/usr/lib/python3/dist-packages/requests/api.py", line 61, in request
    return session.request(method=method, url=url, **kwargs)
  File "/usr/lib/python3/dist-packages/requests/sessions.py", line 544, in request
    resp = self.send(prep, **send_kwargs)
  File "/usr/lib/python3/dist-packages/requests/sessions.py", line 657, in send
    r = adapter.send(request, **kwargs)
  File "/usr/lib/python3/dist-packages/requests/adapters.py", line 516, in send
    raise ConnectionError(e, request=request)
requests.exceptions.ConnectionError: HTTPSConnectionPool(host='api.transferwise.com', port=443): Max retries exceeded with url: /v1/transfers?profile=25518118&limit=100&createdDateStart=2023-09-10&createdDateEnd=2023-09-30&offset=0 (Caused by NewConnectionError('<urllib3.connection.HTTPSConnection object at 0x7f58d2a666b0>: Failed to establish a new connection: [Errno -3] Temporary failure in name resolution'))

During handling of the above exception, another exception occurred:

Traceback (most recent call last):
  File "/home/viktor/Documents/OC-coding/OC-Wise-Fortnox-integration/script_get_wise_transactions_book_and_match.py", line 146, in <module>
    sendErrorEmail(e)
  File "/home/viktor/Documents/OC-coding/OC-Wise-Fortnox-integration/send_error_message_email.py", line 32, in sendErrorEmail
    response = requests.post(api_url, headers=headers, json=payload)
  File "/usr/lib/python3/dist-packages/requests/api.py", line 119, in post
    return request('post', url, data=data, json=json, **kwargs)
  File "/usr/lib/python3/dist-packages/requests/api.py", line 61, in request
    return session.request(method=method, url=url, **kwargs)
  File "/usr/lib/python3/dist-packages/requests/sessions.py", line 530, in request
    prep = self.prepare_request(req)
  File "/usr/lib/python3/dist-packages/requests/sessions.py", line 458, in prepare_request
    p.prepare(
  File "/usr/lib/python3/dist-packages/requests/models.py", line 319, in prepare
    self.prepare_body(data, files, json)
  File "/usr/lib/python3/dist-packages/requests/models.py", line 469, in prepare_body
    body = complexjson.dumps(json)
  File "/usr/lib/python3.10/json/__init__.py", line 231, in dumps
    return _default_encoder.encode(obj)
  File "/usr/lib/python3.10/json/encoder.py", line 199, in encode
    chunks = self.iterencode(o, _one_shot=True)
  File "/usr/lib/python3.10/json/encoder.py", line 257, in iterencode
    return _iterencode(o, 0)
  File "/usr/lib/python3.10/json/encoder.py", line 179, in default
    raise TypeError(f'Object of type {o.__class__.__name__} '
TypeError: Object of type ConnectionError is not JSON serializable
script finished!
Fortnox tokens refreshed!
starting script..
days since OC token was created: 27
rows in wise completed:
9
All rows from OC:
1475
rows in joined list:
8
Script ran successfully at: 2023-12-11
-------------------------------------------------------------------------------------------------------

script finished!
